Workbook

Sheet Answer
A1: Project NOVADRIVE – CRO answer on one page
A2: Management question: Where are our most material supplier-network vulnerabilities, how confident are we, and what practical sourcing options do we have when a supplier becomes a concern?
A4: 1. WHERE ARE WE MOST VULNERABLE?
A5: ="(a) One flood-watch zone sits behind 100% of revenue. East Delta (Z01) hosts IonPeak – the only qualified die source for BOTH power assemblers – and Jade – the only substrate source for every control and battery board. Weekly revenue exposed: "&TEXT(Scorecard!AJ15,"$#,##0.0")&"m. Revenue-at-risk over the die re-qualification window: "&TEXT(Scorecard!AK15,"$#,##0")&"m (no buffer). EV-001 is a WATCH, not damage: verify and pre-position now." -> (a) One flood-watch zone sits behind 100% of revenue. East Delta (Z01) hosts IonPeak – the only qualified die source for BOTH power assemblers – and Jade – the only substrate source for every control and battery board. Weekly revenue exposed: $30.0m. Revenue-at-risk over the die re-qualification window: $1,080m (no buffer). EV-001 is a WATCH, not damage: verify and pre-position now.
A6: ="(b) Our dual sourcing is largely an illusion. M10/M20 look 60/40 and 70/30, but CommonSpan owns both assemblers and both use the same IonPeak dies, Orion ceramics and Lumen magnetics: effective independent sources fall from "&TEXT(Concentration!D5,"0.00")&" to 1.0. B10's 80/20 split collapses from "&TEXT(Concentration!D11,"0.00")&" to 1.0 at the Jade substrate." -> (b) Our dual sourcing is largely an illusion. M10/M20 look 60/40 and 70/30, but CommonSpan owns both assemblers and both use the same IonPeak dies, Orion ceramics and Lumen magnetics: effective independent sources fall from 1.92 to 1.0. B10's 80/20 split collapses from 1.47 to 1.0 at the Jade substrate.
A7: ="(c) The capacitor chain is under live financial stress. Meridian (film for Delta's 100%-allocated C20) has the network's worst finances – current ratio "&TEXT(Scorecard!K21,"0.00")&", net debt/EBITDA "&TEXT(Scorecard!L21,"0.0")&"x, OTD "&TEXT(Scorecard!M21,"0.0")&"% ("&TEXT(Scorecard!N21,"0.0")&"pp) – and EV-003 confirms covenant talks. Meridian's film feeds Delta's C20 capacitor, on which "&TEXT(Scorecard!AI9,"0%")&" of revenue depends (Delta's exposure; Meridian inherits it as Delta's only mapped film supplier)." -> (c) The capacitor chain is under live financial stress. Meridian (film for Delta's 100%-allocated C20) has the network's worst finances – current ratio 0.62, net debt/EBITDA 7.2x, OTD 76.4% (-17.6pp) – and EV-003 confirms covenant talks. Meridian's film feeds Delta's C20 capacitor, on which 73% of revenue depends (Delta's exposure; Meridian inherits it as Delta's only mapped film supplier).
A8: ="(d) Cobalt is a single Tier-1 source for the control board in ALL three products, in a high-hazard zone (Z04). Revenue-at-risk over its 12-week qualification: "&TEXT(Scorecard!AK8,"$#,##0")&"m. Z04 is a second zone that could stop 100% of revenue." -> (d) Cobalt is a single Tier-1 source for the control board in ALL three products, in a high-hazard zone (Z04). Revenue-at-risk over its 12-week qualification: $360m. Z04 is a second zone that could stop 100% of revenue.
A9: (e) Two of the top five (Umber SiC wafers #1, Verdant gases #5) are Tier-3 nodes with sparse data. They rank high because we refuse to treat unknowns as safe – the action is VERIFY, not switch.
A11: Top-10 priority nodes (live from Scorecard)
A12: Rank | B12: Supplier | C12: Tier | D12: Zone | E12: Priority | F12: Band | G12: Confidence | H12: Recommended action | I12: RaR over TTR ($m)
A13: 1 | B13: =INDEX(Scorecard!$B$6:$B$30,MATCH(1,Scorecard!$AP$6:$AP$30,0)) -> Umber Silicon Carbide Ltd. | C13: =INDEX(Scorecard!$C$6:$C$30,MATCH(1,Scorecard!$AP$6:$AP$30,0)) -> 3 | D13: =INDEX(Scorecard!$F$6:$F$30,MATCH(1,Scorecard!$AP$6:$AP$30,0)) -> Z01 | E13: =INDEX(Scorecard!$AO$6:$AO$30,MATCH(1,Scorecard!$AP$6:$AP$30,0)) -> 51.082111 | F13: =INDEX(Scorecard!$AQ$6:$AQ$30,MATCH(1,Scorecard!$AP$6:$AP$30,0)) -> Critical | G13: =INDEX(Scorecard!$AX$6:$AX$30,MATCH(1,Scorecard!$AP$6:$AP$30,0)) -> Low | H13: =INDEX(Scorecard!$AY$6:$AY$30,MATCH(1,Scorecard!$AP$6:$AP$30,0)) -> VERIFY first – urgent sub-tier fact-find | I13: =INDEX(Scorecard!$AK$6:$AK$30,MATCH(1,Scorecard!$AP$6:$AP$30,0)) -> 1080
A14: 2 | B14: =INDEX(Scorecard!$B$6:$B$30,MATCH(2,Scorecard!$AP$6:$AP$30,0)) -> IonPeak Semiconductor Ltd. | C14: =INDEX(Scorecard!$C$6:$C$30,MATCH(2,Scorecard!$AP$6:$AP$30,0)) -> 2 | D14: =INDEX(Scorecard!$F$6:$F$30,MATCH(2,Scorecard!$AP$6:$AP$30,0)) -> Z01 | E14: =INDEX(Scorecard!$AO$6:$AO$30,MATCH(2,Scorecard!$AP$6:$AP$30,0)) -> 47.043111 | F14: =INDEX(Scorecard!$AQ$6:$AQ$30,MATCH(2,Scorecard!$AP$6:$AP$30,0)) -> Critical | G14: =INDEX(Scorecard!$AX$6:$AX$30,MATCH(2,Scorecard!$AP$6:$AP$30,0)) -> High | H14: =INDEX(Scorecard!$AY$6:$AY$30,MATCH(2,Scorecard!$AP$6:$AP$30,0)) -> ACT – mitigate now | I14: =INDEX(Scorecard!$AK$6:$AK$30,MATCH(2,Scorecard!$AP$6:$AP$30,0)) -> 1080
A15: 3 | B15: =INDEX(Scorecard!$B$6:$B$30,MATCH(3,Scorecard!$AP$6:$AP$30,0)) -> Meridian Dielectrics Ltd. | C15: =INDEX(Scorecard!$C$6:$C$30,MATCH(3,Scorecard!$AP$6:$AP$30,0)) -> 2 | D15: =INDEX(Scorecard!$F$6:$F$30,MATCH(3,Scorecard!$AP$6:$AP$30,0)) -> Z03 | E15: =INDEX(Scorecard!$AO$6:$AO$30,MATCH(3,Scorecard!$AP$6:$AP$30,0)) -> 45.068444 | F15: =INDEX(Scorecard!$AQ$6:$AQ$30,MATCH(3,Scorecard!$AP$6:$AP$30,0)) -> Critical | G15: =INDEX(Scorecard!$AX$6:$AX$30,MATCH(3,Scorecard!$AP$6:$AP$30,0)) -> Medium | H15: =INDEX(Scorecard!$AY$6:$AY$30,MATCH(3,Scorecard!$AP$6:$AP$30,0)) -> ACT – mitigate now | I15: =INDEX(Scorecard!$AK$6:$AK$30,MATCH(3,Scorecard!$AP$6:$AP$30,0)) -> 264
A16: 4 | B16: =INDEX(Scorecard!$B$6:$B$30,MATCH(4,Scorecard!$AP$6:$AP$30,0)) -> Jade Printed Circuits Ltd. | C16: =INDEX(Scorecard!$C$6:$C$30,MATCH(4,Scorecard!$AP$6:$AP$30,0)) -> 2 | D16: =INDEX(Scorecard!$F$6:$F$30,MATCH(4,Scorecard!$AP$6:$AP$30,0)) -> Z01 | E16: =INDEX(Scorecard!$AO$6:$AO$30,MATCH(4,Scorecard!$AP$6:$AP$30,0)) -> 42.086667 | F16: =INDEX(Scorecard!$AQ$6:$AQ$30,MATCH(4,Scorecard!$AP$6:$AP$30,0)) -> High | G16: =INDEX(Scorecard!$AX$6:$AX$30,MATCH(4,Scorecard!$AP$6:$AP$30,0)) -> High | H16: =INDEX(Scorecard!$AY$6:$AY$30,MATCH(4,Scorecard!$AP$6:$AP$30,0)) -> ACT – mitigate now | I16: =INDEX(Scorecard!$AK$6:$AK$30,MATCH(4,Scorecard!$AP$6:$AP$30,0)) -> 360
A17: 5 | B17: =INDEX(Scorecard!$B$6:$B$30,MATCH(5,Scorecard!$AP$6:$AP$30,0)) -> Verdant Process Gases Ltd. | C17: =INDEX(Scorecard!$C$6:$C$30,MATCH(5,Scorecard!$AP$6:$AP$30,0)) -> 3 | D17: =INDEX(Scorecard!$F$6:$F$30,MATCH(5,Scorecard!$AP$6:$AP$30,0)) -> Z01 | E17: =INDEX(Scorecard!$AO$6:$AO$30,MATCH(5,Scorecard!$AP$6:$AP$30,0)) -> 36.570333 | F17: =INDEX(Scorecard!$AQ$6:$AQ$30,MATCH(5,Scorecard!$AP$6:$AP$30,0)) -> High | G17: =INDEX(Scorecard!$AX$6:$AX$30,MATCH(5,Scorecard!$AP$6:$AP$30,0)) -> Low | H17: =INDEX(Scorecard!$AY$6:$AY$30,MATCH(5,Scorecard!$AP$6:$AP$30,0)) -> VERIFY first – urgent sub-tier fact-find | I17: =INDEX(Scorecard!$AK$6:$AK$30,MATCH(5,Scorecard!$AP$6:$AP$30,0)) -> 240
A18: 6 | B18: =INDEX(Scorecard!$B$6:$B$30,MATCH(6,Scorecard!$AP$6:$AP$30,0)) -> Orion Ceramics Ltd. | C18: =INDEX(Scorecard!$C$6:$C$30,MATCH(6,Scorecard!$AP$6:$AP$30,0)) -> 2 | D18: =INDEX(Scorecard!$F$6:$F$30,MATCH(6,Scorecard!$AP$6:$AP$30,0)) -> Z01 | E18: =INDEX(Scorecard!$AO$6:$AO$30,MATCH(6,Scorecard!$AP$6:$AP$30,0)) -> 33.006667 | F18: =INDEX(Scorecard!$AQ$6:$AQ$30,MATCH(6,Scorecard!$AP$6:$AP$30,0)) -> High | G18: =INDEX(Scorecard!$AX$6:$AX$30,MATCH(6,Scorecard!$AP$6:$AP$30,0)) -> Medium | H18: =INDEX(Scorecard!$AY$6:$AY$30,MATCH(6,Scorecard!$AP$6:$AP$30,0)) -> CONFIRM sole-source status, then qualify alternate | I18: =INDEX(Scorecard!$AK$6:$AK$30,MATCH(6,Scorecard!$AP$6:$AP$30,0)) -> 600
A19: 7 | B19: =INDEX(Scorecard!$B$6:$B$30,MATCH(7,Scorecard!$AP$6:$AP$30,0)) -> Lumen Magnetics Ltd. | C19: =INDEX(Scorecard!$C$6:$C$30,MATCH(7,Scorecard!$AP$6:$AP$30,0)) -> 2 | D19: =INDEX(Scorecard!$F$6:$F$30,MATCH(7,Scorecard!$AP$6:$AP$30,0)) -> Z04 | E19: =INDEX(Scorecard!$AO$6:$AO$30,MATCH(7,Scorecard!$AP$6:$AP$30,0)) -> 31.636056 | F19: =INDEX(Scorecard!$AQ$6:$AQ$30,MATCH(7,Scorecard!$AP$6:$AP$30,0)) -> High | G19: =INDEX(Scorecard!$AX$6:$AX$30,MATCH(7,Scorecard!$AP$6:$AP$30,0)) -> Medium | H19: =INDEX(Scorecard!$AY$6:$AY$30,MATCH(7,Scorecard!$AP$6:$AP$30,0)) -> CONFIRM sole-source status, then qualify alternate | I19: =INDEX(Scorecard!$AK$6:$AK$30,MATCH(7,Scorecard!$AP$6:$AP$30,0)) -> 300
A20: 8 | B20: =INDEX(Scorecard!$B$6:$B$30,MATCH(8,Scorecard!$AP$6:$AP$30,0)) -> Warden Copper Foil Ltd. | C20: =INDEX(Scorecard!$C$6:$C$30,MATCH(8,Scorecard!$AP$6:$AP$30,0)) -> 3 | D20: =INDEX(Scorecard!$F$6:$F$30,MATCH(8,Scorecard!$AP$6:$AP$30,0)) -> Z06 | E20: =INDEX(Scorecard!$AO$6:$AO$30,MATCH(8,Scorecard!$AP$6:$AP$30,0)) -> 30.913917 | F20: =INDEX(Scorecard!$AQ$6:$AQ$30,MATCH(8,Scorecard!$AP$6:$AP$30,0)) -> High | G20: =INDEX(Scorecard!$AX$6:$AX$30,MATCH(8,Scorecard!$AP$6:$AP$30,0)) -> Low | H20: =INDEX(Scorecard!$AY$6:$AY$30,MATCH(8,Scorecard!$AP$6:$AP$30,0)) -> VERIFY first – urgent sub-tier fact-find | I20: =INDEX(Scorecard!$AK$6:$AK$30,MATCH(8,Scorecard!$AP$6:$AP$30,0)) -> 240
A21: 9 | B21: =INDEX(Scorecard!$B$6:$B$30,MATCH(9,Scorecard!$AP$6:$AP$30,0)) -> Cobalt Control Electronics Ltd. | C21: =INDEX(Scorecard!$C$6:$C$30,MATCH(9,Scorecard!$AP$6:$AP$30,0)) -> 1 | D21: =INDEX(Scorecard!$F$6:$F$30,MATCH(9,Scorecard!$AP$6:$AP$30,0)) -> Z04 | E21: =INDEX(Scorecard!$AO$6:$AO$30,MATCH(9,Scorecard!$AP$6:$AP$30,0)) -> 30.785556 | F21: =INDEX(Scorecard!$AQ$6:$AQ$30,MATCH(9,Scorecard!$AP$6:$AP$30,0)) -> High | G21: =INDEX(Scorecard!$AX$6:$AX$30,MATCH(9,Scorecard!$AP$6:$AP$30,0)) -> High | H21: =INDEX(Scorecard!$AY$6:$AY$30,MATCH(9,Scorecard!$AP$6:$AP$30,0)) -> ACT – mitigate now | I21: =INDEX(Scorecard!$AK$6:$AK$30,MATCH(9,Scorecard!$AP$6:$AP$30,0)) -> 360
A22: 10 | B22: =INDEX(Scorecard!$B$6:$B$30,MATCH(10,Scorecard!$AP$6:$AP$30,0)) -> Xenon Resin Ltd. | C22: =INDEX(Scorecard!$C$6:$C$30,MATCH(10,Scorecard!$AP$6:$AP$30,0)) -> 3 | D22: =INDEX(Scorecard!$F$6:$F$30,MATCH(10,Scorecard!$AP$6:$AP$30,0)) -> Z04 | E22: =INDEX(Scorecard!$AO$6:$AO$30,MATCH(10,Scorecard!$AP$6:$AP$30,0)) -> 30.460306 | F22: =INDEX(Scorecard!$AQ$6:$AQ$30,MATCH(10,Scorecard!$AP$6:$AP$30,0)) -> High | G22: =INDEX(Scorecard!$AX$6:$AX$30,MATCH(10,Scorecard!$AP$6:$AP$30,0)) -> Low | H22: =INDEX(Scorecard!$AY$6:$AY$30,MATCH(10,Scorecard!$AP$6:$AP$30,0)) -> VERIFY first – urgent sub-tier fact-find | I22: =INDEX(Scorecard!$AK$6:$AK$30,MATCH(10,Scorecard!$AP$6:$AP$30,0)) -> 240
A24: 2. HOW CONFIDENT ARE WE?
A25: ="Network links: "&COUNTIF(Network!S5:S36,"A")&" grade A (≥2 independent source families), "&COUNTIF(Network!S5:S36,"B")&" grade B (one primary disclosure), "&COUNTIF(Network!S5:S36,"C")&" grade C (inferred), plus "&COUNTIF(Network!R37:R45,"Hypothesis")&" hypotheses and "&COUNTIF(Network!R37:R45,"Rejected")&" rejected traps. Every Tier-1 link is grade A." -> Network links: 15 grade A (≥2 independent source families), 16 grade B (one primary disclosure), 1 grade C (inferred), plus 2 hypotheses and 3 rejected traps. Every Tier-1 link is grade A.
A26: ="Scored nodes: "&COUNTIF(Scorecard!AX6:AX30,"High")&" High, "&COUNTIF(Scorecard!AX6:AX30,"Medium")&" Medium, "&COUNTIF(Scorecard!AX6:AX30,"Low")&" Low confidence. Confidence is kept separate from risk: it decides whether we ACT or VERIFY." -> Scored nodes: 11 High, 8 Medium, 6 Low confidence. Confidence is kept separate from risk: it decides whether we ACT or VERIFY.
A27: ="Robustness: IonPeak, Jade, Umber and Verdant stay top-5 under all 5 weighting scenarios; Meridian under "&Sensitivity!U28&" of 5 (Sensitivity tab). Our headline conclusions do not hinge on the weights." -> Robustness: IonPeak, Jade, Umber and Verdant stay top-5 under all 5 weighting scenarios; Meridian under 4 of 5 (Sensitivity tab). Our headline conclusions do not hinge on the weights.
A28: Biggest unknowns: whether Meridian is Delta's only film source; whether NovaDrive dies are SiC (Umber relevance); inventory at every tier; the zones of NovaDrive's own plants; which lanes use Gulf Arc (Unknowns tab).
A30: 3. WHAT ARE OUR PRACTICAL SOURCING OPTIONS?
A31: Capacitors (fastest hedge, 8-week qualification): TDK B25696H (Jun-2026) and Vishay MKP1848e (Sep-2025) as a second Tier-1 C20; Toray / Tervakoski as second film for Delta. Steinerfilm US EXCLUDED – plant closed June 2026.
A32: Power dies / modules: Infineon (bare dies + modules), Mitsubishi 8th-gen NX (May-2026), Fuji X-Series for M10; Vincotech / Infineon SiC for M20. Wolfspeed RESERVE only (fitment 72, Amber risk: emerged from Chapter 11 on 30-Sep-2025). Independent assembler: Semikron Danfoss power stacks (must not use IonPeak dies or Orion ceramics).
A33: Control boards: second EMS (Sanmina, Celestica, Kitron) – only real once NovaDrive owns the C10 data pack. Substrates outside Z01: Schweizer (small; profitable again in 2025) or TTM Penang.
A34: Cooling: Boyd (now Eaton, Mar-2026 – watch capacity diverted to data centres) or Wieland Microcool. Full scoring on Alternates tab: fitment and risk screened SEPARATELY.
A36: 4. WHAT WE WOULD DO ON MONDAY
A37: ① Z01 census + pull-forward through the Tier-1s (EV-001).
A38: ② Delta film-source disclosure + C20 buffer ≥ 8 weeks; launch second C20 qualification (EV-003).
A39: ③ N-tier disclosure request for all presumed-sole links.
A40: ④ Secure the C10 data pack from Cobalt; brief two EMS candidates.
A41: ⑤ Open the second power-module platform programme – the only structural fix for the CommonSpan/IonPeak concentration.
... A51: HOW TO READ THIS WORKBOOK: Answer → Scorecard (priority) → Network & Evidence (why we believe each link) → Concentration → Alerts → Alternates → ActionPlan → Unknowns. Blue = input/judgement, black = formula, green = cross-tab link, yellow = key assumption. Change any weight on Assumptions and everything recalculates.

Sheet Scorecard
A1: Supplier risk scorecard – Impact × Vulnerability, with Confidence kept separate
A2: Priority = Impact × Vulnerability / 100. Confidence (evidence quality + data completeness + dependency certainty) does NOT change the score – it changes the ACTION (act vs verify).
A4: IDENTITY & NETWORK ROLE | K4: RAW INDICATORS (from case data, via Data tab) | S4: VULNERABILITY / LIKELIHOOD (0-100) | AE4: IMPACT, PRIORITY & RANK | AS4: CONFIDENCE (kept separate) & RECOMMENDED ACTION
A5: Node ID | B5: Supplier | C5: Tier | D5: Network role | E5: Facility | F5: Zone | G5: Dependency status | H5: Downstream Tier-1s | I5: TTR (weeks) | J5: TTR basis | K5: Current ratio | L5: Net debt/EBITDA | M5: OTD 3m % | N5: OTD Δ pp | O5: Assurance gap | P5: Physical hazard | Q5: Logistics friction | R5: Infrastructure | S5: Leverage score | T5: Liquidity score | U5: OTD score | V5: OTD trend score | W5: Leverage used | X5: Liquidity used | Y5: Assurance used | Z5: Financial | AA5: Operational | AB5: Geographic | AC5: Event overlay (1=yes) | AD5: VULNERABILITY | AE5: Exposure P1 | AF5: Exposure P2 | AG5: Exposure P3 | AH5: Revenue exposed ($m/yr) | AI5: Share of revenue | AJ5: Weekly revenue exposed ($m) | AK5: Revenue-at-risk over TTR ($m) | AL5: Recovery score | AM5: Centrality score | AN5: IMPACT | AO5: PRIORITY | AP5: Rank | AQ5: Band | AR5: Quadrant | AS5: Link grade pts | AT5: Indicators available (of 8) | AU5: Data pts | AV5: Dependency pts | AW5: Confidence pts | AX5: CONFIDENCE | AY5: Recommended action | AZ5: Missing data (imputed)
A6: ORG-247 | B6: =INDEX(Data!$B$5:$B$34,MATCH($A6,Data!$A$5:$A$34,0)) -> Aster Power Assemblies Ltd. | C6: 1 | D6: Tier-1: M10 (60%) & M20 (70%) | E6: =INDEX(Data!$G$38:$G$67,MATCH($A6,Data!$A$38:$A$67,0)) -> SITE-018 | F6: =INDEX(Data!$I$38:$I$67,MATCH($A6,Data!$A$38:$A$67,0)) -> Z02 | G6: Partial (60/70%) – shares owner with Boreal | H6: 1 | I6: 16 | J6: Case: M10/M20 qualification lead time 16 wks | K6: =IF(INDEX(Data!$C$5:$C$34,MATCH($A6,Data!$A$5:$A$34,0))="","",INDEX(Data!$C$5:$C$34,MATCH($A6,Data!$A$5:$A$34,0))) -> 2.13 | L6: =IF(INDEX(Data!$D$5:$D$34,MATCH($A6,Data!$A$5:$A$34,0))="","",INDEX(Data!$D$5:$D$34,MATCH($A6,Data!$A$5:$A$34,0))) -> 2 | M6: =IF(INDEX(Data!$E$5:$E$34,MATCH($A6,Data!$A$5:$A$34,0))="","",INDEX(Data!$E$5:$E$34,MATCH($A6,Data!$A$5:$A$34,0))) -> 80.9 | N6: =IF(INDEX(Data!$F$5:$F$34,MATCH($A6,Data!$A$5:$A$34,0))="","",INDEX(Data!$F$5:$F$34,MATCH($A6,Data!$A$5:$A$34,0))) -> 2.3 | O6: =IF(INDEX(Data!$G$5:$G$34,MATCH($A6,Data!$A$5:$A$34,0))="","",INDEX(Data!$G$5:$G$34,MATCH($A6,Data!$A$5:$A$34,0))) -> 24 | P6: =IF(INDEX(Data!$H$5:$H$34,MATCH($A6,Data!$A$5:$A$34,0))="","",INDEX(Data!$H$5:$H$34,MATCH($A6,Data!$A$5:$A$34,0))) -> 27 | Q6: =IF(INDEX(Data!$I$5:$I$34,MATCH($A6,Data!$A$5:$A$34,0))="","",INDEX(Data!$I$5:$I$34,MATCH($A6,Data!$A$5:$A$34,0))) -> 30 | R6: =IF(INDEX(Data!$J$5:$J$34,MATCH($A6,Data!$A$5:$A$34,0))="","",INDEX(Data!$J$5:$J$34,MATCH($A6,Data!$A$5:$A$34,0))) -> 24 | S6: =IF(L6="","",IF(L6<=Assumptions!$B$31,Assumptions!$H$31,IF(L6<=Assumptions!$C$31,Assumptions!$H$31+(L6-Assumptions!$B$31)/(Assumptions!$C$31-Assumptions!$B$31)*(Assumptions!$I$31-Assumptions!$H$31),IF(L6<=Assumptions!$D$31,Assumptions!$I$31+(L6-Assumptions!$C$31)/(Assumptions!$D$31-Assumptions!$C$31)*(Assumptions!$J$31-Assumptions!$I$31),IF(L6<=Assumptions!$E$31,Assumptions!$J$31+(L6-Assumptions!$D$31)/(Assumptions!$E$31-Assumptions!$D$31)*(Assumptions!$K$31-Assumptions!$J$31),IF(L6<=Assumptions!$F$31,Assumptions!$K$31+(L6-Assumptions!$E$31)/(Assumptions!$F$31-Assumptions!$E$31)*(Assumptions!$L$31-Assumptions!$K$31),IF(L6<=Assumptions!$G$31,Assumptions!$L$31+(L6-Assumptions!$F$31)/(Assumptions!$G$31-Assumptions!$F$31)*(Assumptions!$M$31-Assumptions!$L$31),Assumptions!$M$31))))))) -> 24 | T6: =IF(K6="","",IF(K6<=Assumptions!$B$32,Assumptions!$H$32,IF(K6<=Assumptions!$C$32,Assumptions!$H$32+(K6-Assumptions!$B$32)/(Assumptions!$C$32-Assumptions!$B$32)*(Assumptions!$I$32-Assumptions!$H$32),IF(K6<=Assumptions!$D$32,Assumptions!$I$32+(K6-Assumptions!$C$32)/(Assumptions!$D$32-Assumptions!$C$32)*(Assumptions!$J$32-Assumptions!$I$32),IF(K6<=Assumptions!$E$32,Assumptions!$J$32+(K6-Assumptions!$D$32)/(Assumptions!$E$32-Assumptions!$D$32)*(Assumptions!$K$32-Assumptions!$J$32),IF(K6<=Assumptions!$F$32,Assumptions!$K$32+(K6-Assumptions!$E$32)/(Assumptions!$F$32-Assumptions!$E$32)*(Assumptions!$L$32-Assumptions!$K$32),IF(K6<=Assumptions!$G$32,Assumptions!$L$32+(K6-Assumptions!$F$32)/(Assumptions!$G$32-Assumptions!$F$32)*(Assumptions!$M$32-Assumptions!$L$32),Assumptions!$M$32))))))) -> 11.1 | U6: =IF(M6<=Assumptions!$B$33,Assumptions!$H$33,IF(M6<=Assumptions!$C$33,Assumptions!$H$33+(M6-Assumptions!$B$33)/(Assumptions!$C$33-Assumptions!$B$33)*(Assumptions!$I$33-Assumptions!$H$33),IF(M6<=Assumptions!$D$33,Assumptions!$I$33+(M6-Assumptions!$C$33)/(Assumptions!$D$33-Assumptions!$C$33)*(Assumptions!$J$33-Assumptions!$I$33),IF(M6<=Assumptions!$E$33,Assumptions!$J$33+(M6-Assumptions!$D$33)/(Assumptions!$E$33-Assumptions!$D$33)*(Assumptions!$K$33-Assumptions!$J$33),IF(M6<=Assumptions!$F$33,Assumptions!$K$33+(M6-Assumptions!$E$33)/(Assumptions!$F$33-Assumptions!$E$33)*(Assumptions!$L$33-Assumptions!$K$33),IF(M6<=Assumptions!$G$33,Assumptions!$L$33+(M6-Assumptions!$F$33)/(Assumptions!$G$33-Assumptions!$F$33)*(Assumptions!$M$33-Assumptions!$L$33),Assumptions!$M$33)))))) -> 70.5 | V6: =IF(N6<=Assumptions!$B$34,Assumptions!$H$34,IF(N6<=Assumptions!$C$34,Assumptions!$H$34+(N6-Assumptions!$B$34)/(Assumptions!$C$34-Assumptions!$B$34)*(Assumptions!$I$34-Assumptions!$H$34),IF(N6<=Assumptions!$D$34,Assumptions!$I$34+(N6-Assumptions!$C$34)/(Assumptions!$D$34-Assumptions!$C$34)*(Assumptions!$J$34-Assumptions!$I$34),IF(N6<=Assumptions!$E$34,Assumptions!$J$34+(N6-Assumptions!$D$34)/(Assumptions!$E$34-Assumptions!$D$34)*(Assumptions!$K$34-Assumptions!$J$34),IF(N6<=Assumptions!$F$34,Assumptions!$K$34+(N6-Assumptions!$E$34)/(Assumptions!$F$34-Assumptions!$E$34)*(Assumptions!$L$34-Assumptions!$K$34),IF(N6<=Assumptions!$G$34,Assumptions!$L$34+(N6-Assumptions!$F$34)/(Assumptions!$G$34-Assumptions!$F$34)*(Assumptions!$M$34-Assumptions!$L$34),Assumptions!$M$34)))))) -> 0 | W6: =IF(S6="",PERCENTILE($S$6:$S$30,Assumptions!$B$36),S6) -> 24 | X6: =IF(T6="",PERCENTILE($T$6:$T$30,Assumptions!$B$36),T6) -> 11.1 | Y6: =IF(O6="",PERCENTILE($O$6:$O$30,Assumptions!$B$36),O6) -> 24 | Z6: =W6*Assumptions!$B$16+X6*Assumptions!$B$17 -> 17.55 | AA6: =U6*Assumptions!$B$18+V6*Assumptions!$B$19 -> 35.25 | AB6: =AVERAGE(P6:R6) -> 27 | AC6: 0 | AD6: =MIN(100,Z6*Assumptions!$B$11+AA6*Assumptions!$B$12+Y6*Assumptions!$B$13+AB6*Assumptions!$B$14+AC6*Assumptions!$B$20) -> 26.19 | AE6: =MIN(1,SUMIFS(Network!$V$5:$V$14,Network!$D$5:$D$14,$A6,Network!$U$5:$U$14,1)) -> 0.6 | AF6: =MIN(1,SUMIFS(Network!$W$5:$W$14,Network!$D$5:$D$14,$A6,Network!$U$5:$U$14,1)) -> 0.7 | AG6: =MIN(1,SUMIFS(Network!$X$5:$X$14,Network!$D$5:$D$14,$A6,Network!$U$5:$U$14,1)) -> 0.6 | AH6: =AE6*Assumptions!$B$5+AF6*Assumptions!$B$6+AG6*Assumptions!$B$7 -> 988 | AI6: =AH6/Assumptions!$B$8 -> 0.63333333 | AJ6: =AH6/52 -> 19 | AK6: =AJ6*I6 -> 304 | AL6: =MIN(100,I6/Assumptions!$B$26*100) -> 44.444444 | AM6: =MIN(100,H6/Assumptions!$B$27*100) -> 33.333333 | AN6: =AI6*100*Assumptions!$B$23+AL6*Assumptions!$B$24+AM6*Assumptions!$B$25 -> 51.666667 | AO6: =AN6*AD6/100 -> 13.5315 | AP6: =RANK(AO6,$AO$6:$AO$30)+COUNTIF($AO$6:AO6,AO6)-1 -> 19 | AQ6: =IF(AO6>=Assumptions!$B$39,"Critical",IF(AO6>=Assumptions!$B$40,"High",IF(AO6>=Assumptions!$B$41,"Elevated","Watch"))) -> Watch | AR6: =IF(AND(AN6>=Assumptions!$B$42,AD6>=Assumptions!$B$43),"Act now",IF(AN6>=Assumptions!$B$42,"Protect (structural)",IF(AD6>=Assumptions!$B$43,"Remediate supplier","Routine"))) -> Routine | AS6: =_xlfn.MAXIFS(Network!$T$5:$T$36,Network!$D$5:$D$36,$A6) -> 3 | AT6: =COUNT(K6:R6) -> 8 | AU6: =IF(AT6>=8,2,IF(AT6>=6,1,0)) -> 2 | AV6: =IF(OR(C6=1,LEFT(G6,9)="Confirmed"),1,0) -> 1 | AW6: =AS6+AU6+AV6 -> 6 | AX6: =IF(AW6>=Assumptions!$B$44,"High",IF(AW6>=Assumptions!$B$45,"Medium","Low")) -> High | AY6: =IF(OR(AQ6="Critical",AQ6="High"),IF(AX6="Low","VERIFY first – urgent sub-tier fact-find",IF(OR(AQ6="Critical",AV6=1),"ACT – mitigate now","CONFIRM sole-source status, then qualify alternate")),IF(AQ6="Elevated",IF(AX6="Low","VERIFY – add to N-tier survey","PLAN – qualify alternate in 90 days"),"MONITOR – quarterly review")) -> MONITOR – quarterly review | AZ6: =IF(K6&L6&O6<>"",IF(OR(K6="",L6="",O6=""),TRIM(IF(K6="","Current ratio; ","")&IF(L6="","Net debt/EBITDA; ","")&IF(O6="","Assurance gap","")),"—"),"Current ratio; Net debt/EBITDA; Assurance gap") -> —
A7: ORG-725 | B7: =INDEX(Data!$B$5:$B$34,MATCH($A7,Data!$A$5:$A$34,0)) -> Boreal Power Systems Ltd. | C7: 1 | D7: Tier-1: M10 (40%) & M20 (30%) | E7: =INDEX(Data!$G$38:$G$67,MATCH($A7,Data!$A$38:$A$67,0)) -> SITE-025 | F7: =INDEX(Data!$I$38:$I$67,MATCH($A7,Data!$A$38:$A$67,0)) -> Z05 | G7: Partial (40/30%) – shares owner with Aster | H7: 1 | I7: 16 | J7: Case: M10/M20 qualification lead time 16 wks | K7: =IF(INDEX(Data!$C$5:$C$34,MATCH($A7,Data!$A$5:$A$34,0))="","",INDEX(Data!$C$5:$C$34,MATCH($A7,Data!$A$5:$A$34,0))) -> 1.54 | L7: =IF(INDEX(Data!$D$5:$D$34,MATCH($A7,Data!$A$5:$A$34,0))="","",INDEX(Data!$D$5:$D$34,MATCH($A7,Data!$A$5:$A$34,0))) -> 3 | M7: =IF(INDEX(Data!$E$5:$E$34,MATCH($A7,Data!$A$5:$A$34,0))="","",INDEX(Data!$E$5:$E$34,MATCH($A7,Data!$A$5:$A$34,0))) -> 83.1 | N7: =IF(INDEX(Data!$F$5:$F$34,MATCH($A7,Data!$A$5:$A$34,0))="","",INDEX(Data!$F$5:$F$34,MATCH($A7,Data!$A$5:$A$34,0))) -> 2.2 | O7: =IF(INDEX(Data!$G$5:$G$34,MATCH($A7,Data!$A$5:$A$34,0))="","",INDEX(Data!$G$5:$G$34,MATCH($A7,Data!$A$5:$A$34,0))) -> 33 | P7: =IF(INDEX(Data!$H$5:$H$34,MATCH($A7,Data!$A$5:$A$34,0))="","",INDEX(Data!$H$5:$H$34,MATCH($A7,Data!$A$5:$A$34,0))) -> 31 | Q7: =IF(INDEX(Data!$I$5:$I$34,MATCH($A7,Data!$A$5:$A$34,0))="","",INDEX(Data!$I$5:$I$34,MATCH($A7,Data!$A$5:$A$34,0))) -> 23 | R7: =IF(INDEX(Data!$J$5:$J$34,MATCH($A7,Data!$A$5:$A$34,0))="","",INDEX(Data!$J$5:$J$34,MATCH($A7,Data!$A$5:$A$34,0))) -> 19 | S7: =IF(L7="","",IF(L7<=Assumptions!$B$31,Assumptions!$H$31,IF(L7<=Assumptions!$C$31,Assumptions!$H$31+(L7-Assumptions!$B$31)/(Assumptions!$C$31-Assumptions!$B$31)*(Assumptions!$I$31-Assumptions!$H$31),IF(L7<=Assumptions!$D$31,Assumptions!$I$31+(L7-Assumptions!$C$31)/(Assumptions!$D$31-Assumptions!$C$31)*(Assumptions!$J$31-Assumptions!$I$31),IF(L7<=Assumptions!$E$31,Assumptions!$J$31+(L7-Assumptions!$D$31)/(Assumptions!$E$31-Assumptions!$D$31)*(Assumptions!$K$31-Assumptions!$J$31),IF(L7<=Assumptions!$F$31,Assumptions!$K$31+(L7-Assumptions!$E$31)/(Assumptions!$F$31-Assumptions!$E$31)*(Assumptions!$L$31-Assumptions!$K$31),IF(L7<=Assumptions!$G$31,Assumptions!$L$31+(L7-Assumptions!$F$31)/(Assumptions!$G$31-Assumptions!$F$31)*(Assumptions!$M$31-Assumptions!$L$31),Assumptions!$M$31))))))) -> 43.333333 | T7: =IF(K7="","",IF(K7<=Assumptions!$B$32,Assumptions!$H$32,IF(K7<=Assumptions!$C$32,Assumptions!$H$32+(K7-Assumptions!$B$32)/(Assumptions!$C$32-Assumptions!$B$32)*(Assumptions!$I$32-Assumptions!$H$32),IF(K7<=Assumptions!$D$32,Assumptions!$I$32+(K7-Assumptions!$C$32)/(Assumptions!$D$32-Assumptions!$C$32)*(Assumptions!$J$32-Assumptions!$I$32),IF(K7<=Assumptions!$E$32,Assumptions!$J$32+(K7-Assumptions!$D$32)/(Assumptions!$E$32-Assumptions!$D$32)*(Assumptions!$K$32-Assumptions!$J$32),IF(K7<=Assumptions!$F$32,Assumptions!$K$32+(K7-Assumptions!$E$32)/(Assumptions!$F$32-Assumptions!$E$32)*(Assumptions!$L$32-Assumptions!$K$32),IF(K7<=Assumptions!$G$32,Assumptions!$L$32+(K7-Assumptions!$F$32)/(Assumptions!$G$32-Assumptions!$F$32)*(Assumptions!$M$32-Assumptions!$L$32),Assumptions!$M$32))))))) -> 28.8 | U7: =IF(M7<=Assumptions!$B$33,Assumptions!$H$33,IF(M7<=Assumptions!$C$33,Assumptions!$H$33+(M7-Assumptions!$B$33)/(Assumptions!$C$33-Assumptions!$B$33)*(Assumptions!$I$33-Assumptions!$H$33),IF(M7<=Assumptions!$D$33,Assumptions!$I$33+(M7-Assumptions!$C$33)/(Assumptions!$D$33-Assumptions!$C$33)*(Assumptions!$J$33-Assumptions!$I$33),IF(M7<=Assumptions!$E$33,Assumptions!$J$33+(M7-Assumptions!$D$33)/(Assumptions!$E$33-Assumptions!$D$33)*(Assumptions!$K$33-Assumptions!$J$33),IF(M7<=Assumptions!$F$33,Assumptions!$K$33+(M7-Assumptions!$E$33)/(Assumptions!$F$33-Assumptions!$E$33)*(Assumptions!$L$33-Assumptions!$K$33),IF(M7<=Assumptions!$G$33,Assumptions!$L$33+(M7-Assumptions!$F$33)/(Assumptions!$G$33-Assumptions!$F$33)*(Assumptions!$M$33-Assumptions!$L$33),Assumptions!$M$33)))))) -> 59.5 | V7: =IF(N7<=Assumptions!$B$34,Assumptions!$H$34,IF(N7<=Assumptions!$C$34,Assumptions!$H$34+(N7-Assumptions!$B$34)/(Assumptions!$C$34-Assumptions!$B$34)*(Assumptions!$I$34-Assumptions!$H$34),IF(N7<=Assumptions!$D$34,Assumptions!$I$34+(N7-Assumptions!$C$34)/(Assumptions!$D$34-Assumptions!$C$34)*(Assumptions!$J$34-Assumptions!$I$34),IF(N7<=Assumptions!$E$34,Assumptions!$J$34+(N7-Assumptions!$D$34)/(Assumptions!$E$34-Assumptions!$D$34)*(Assumptions!$K$34-Assumptions!$J$34),IF(N7<=Assumptions!$F$34,Assumptions!$K$34+(N7-Assumptions!$E$34)/(Assumptions!$F$34-Assumptions!$E$34)*(Assumptions!$L$34-Assumptions!$K$34),IF(N7<=Assumptions!$G$34,Assumptions!$L$34+(N7-Assumptions!$F$34)/(Assumptions!$G$34-Assumptions!$F$34)*(Assumptions!$M$34-Assumptions!$L$34),Assumptions!$M$34)))))) -> 0 | W7: =IF(S7="",PERCENTILE($S$6:$S$30,Assumptions!$B$36),S7) -> 43.333333 | X7: =IF(T7="",PERCENTILE($T$6:$T$30,Assumptions!$B$36),T7) -> 28.8 | Y7: =IF(O7="",PERCENTILE($O$6:$O$30,Assumptions!$B$36),O7) -> 33 | Z7: =W7*Assumptions!$B$16+X7*Assumptions!$B$17 -> 36.066667 | AA7: =U7*Assumptions!$B$18+V7*Assumptions!$B$19 -> 29.75 | AB7: =AVERAGE(P7:R7) -> 24.333333 | AC7: 0 | AD7: =MIN(100,Z7*Assumptions!$B$11+AA7*Assumptions!$B$12+Y7*Assumptions!$B$13+AB7*Assumptions!$B$14+AC7*Assumptions!$B$20) -> 30.778333 | AE7: =MIN(1,SUMIFS(Network!$V$5:$V$14,Network!$D$5:$D$14,$A7,Network!$U$5:$U$14,1)) -> 0.4 | AF7: =MIN(1,SUMIFS(Network!$W$5:$W$14,Network!$D$5:$D$14,$A7,Network!$U$5:$U$14,1)) -> 0.3 | AG7: =MIN(1,SUMIFS(Network!$X$5:$X$14,Network!$D$5:$D$14,$A7,Network!$U$5:$U$14,1)) -> 0.4 | AH7: =AE7*Assumptions!$B$5+AF7*Assumptions!$B$6+AG7*Assumptions!$B$7 -> 572 | AI7: =AH7/Assumptions!$B$8 -> 0.36666667 | AJ7: =AH7/52 -> 11 | AK7: =AJ7*I7 -> 176 | AL7: =MIN(100,I7/Assumptions!$B$26*100) -> 44.444444 | AM7: =MIN(100,H7/Assumptions!$B$27*100) -> 33.333333 | AN7: =AI7*100*Assumptions!$B$23+AL7*Assumptions!$B$24+AM7*Assumptions!$B$25 -> 38.333333 | AO7: =AN7*AD7/100 -> 11.798361 | AP7: =RANK(AO7,$AO$6:$AO$30)+COUNTIF($AO$6:AO7,AO7)-1 -> 21 | AQ7: =IF(AO7>=Assumptions!$B$39,"Critical",IF(AO7>=Assumptions!$B$40,"High",IF(AO7>=Assumptions!$B$41,"Elevated","Watch"))) -> Watch | AR7: =IF(AND(AN7>=Assumptions!$B$42,AD7>=Assumptions!$B$43),"Act now",IF(AN7>=Assumptions!$B$42,"Protect (structural)",IF(AD7>=Assumptions!$B$43,"Remediate supplier","Routine"))) -> Routine | AS7: =_xlfn.MAXIFS(Network!$T$5:$T$36,Network!$D$5:$D$36,$A7) -> 3 | AT7: =COUNT(K7:R7) -> 8 | AU7: =IF(AT7>=8,2,IF(AT7>=6,1,0)) -> 2 | AV7: =IF(OR(C7=1,LEFT(G7,9)="Confirmed"),1,0) -> 1 | AW7: =AS7+AU7+AV7 -> 6 | AX7: =IF(AW7>=Assumptions!$B$44,"High",IF(AW7>=Assumptions!$B$45,"Medium","Low")) -> High | AY7: =IF(OR(AQ7="Critical",AQ7="High"),IF(AX7="Low","VERIFY first – urgent sub-tier fact-find",IF(OR(AQ7="Critical",AV7=1),"ACT – mitigate now","CONFIRM sole-source status, then qualify alternate")),IF(AQ7="Elevated",IF(AX7="Low","VERIFY – add to N-tier survey","PLAN – qualify alternate in 90 days"),"MONITOR – quarterly review")) -> MONITOR – quarterly review | AZ7: =IF(K7&L7&O7<>"",IF(OR(K7="",L7="",O7=""),TRIM(IF(K7="","Current ratio; ","")&IF(L7="","Net debt/EBITDA; ","")&IF(O7="","Assurance gap","")),"—"),"Current ratio; Net debt/EBITDA; Assurance gap") -> —
A8: ORG-119 | B8: =INDEX(Data!$B$5:$B$34,MATCH($A8,Data!$A$5:$A$34,0)) -> Cobalt Control Electronics Ltd. | C8: 1 | D8: Tier-1: C10 control board, all products | E8: =INDEX(Data!$G$38:$G$67,MATCH($A8,Data!$A$38:$A$67,0)) -> SITE-032 | F8: =INDEX(Data!$I$38:$I$67,MATCH($A8,Data!$A$38:$A$67,0)) -> Z04 | G8: Confirmed sole (100% allocation) | H8: 1 | I8: 12 | J8: Case: C10 qualification 12 wks | K8: =IF(INDEX(Data!$C$5:$C$34,MATCH($A8,Data!$A$5:$A$34,0))="","",INDEX(Data!$C$5:$C$34,MATCH($A8,Data!$A$5:$A$34,0))) -> 2.34 | L8: =IF(INDEX(Data!$D$5:$D$34,MATCH($A8,Data!$A$5:$A$34,0))="","",INDEX(Data!$D$5:$D$34,MATCH($A8,Data!$A$5:$A$34,0))) -> 4 | M8: =IF(INDEX(Data!$E$5:$E$34,MATCH($A8,Data!$A$5:$A$34,0))="","",INDEX(Data!$E$5:$E$34,MATCH($A8,Data!$A$5:$A$34,0))) -> 83.3 | N8: =IF(INDEX(Data!$F$5:$F$34,MATCH($A8,Data!$A$5:$A$34,0))="","",INDEX(Data!$F$5:$F$34,MATCH($A8,Data!$A$5:$A$34,0))) -> -2.3 | O8: =IF(INDEX(Data!$G$5:$G$34,MATCH($A8,Data!$A$5:$A$34,0))="","",INDEX(Data!$G$5:$G$34,MATCH($A8,Data!$A$5:$A$34,0))) -> 42 | P8: =IF(INDEX(Data!$H$5:$H$34,MATCH($A8,Data!$A$5:$A$34,0))="","",INDEX(Data!$H$5:$H$34,MATCH($A8,Data!$A$5:$A$34,0))) -> 58 | Q8: =IF(INDEX(Data!$I$5:$I$34,MATCH($A8,Data!$A$5:$A$34,0))="","",INDEX(Data!$I$5:$I$34,MATCH($A8,Data!$A$5:$A$34,0))) -> 62 | R8: =IF(INDEX(Data!$J$5:$J$34,MATCH($A8,Data!$A$5:$A$34,0))="","",INDEX(Data!$J$5:$J$34,MATCH($A8,Data!$A$5:$A$34,0))) -> 52 | S8: =IF(L8="","",IF(L8<=Assumptions!$B$31,Assumptions!$H$31,IF(L8<=Assumptions!$C$31,Assumptions!$H$31+(L8-Assumptions!$B$31)/(Assumptions!$C$31-Assumptions!$B$31)*(Assumptions!$I$31-Assumptions!$H$31),IF(L8<=Assumptions!$D$31,Assumptions!$I$31+(L8-Assumptions!$C$31)/(Assumptions!$D$31-Assumptions!$C$31)*(Assumptions!$J$31-Assumptions!$I$31),IF(L8<=Assumptions!$E$31,Assumptions!$J$31+(L8-Assumptions!$D$31)/(Assumptions!$E$31-Assumptions!$D$31)*(Assumptions!$K$31-Assumptions!$J$31),IF(L8<=Assumptions!$F$31,Assumptions!$K$31+(L8-Assumptions!$E$31)/(Assumptions!$F$31-Assumptions!$E$31)*(Assumptions!$L$31-Assumptions!$K$31),IF(L8<=Assumptions!$G$31,Assumptions!$L$31+(L8-Assumptions!$F$31)/(Assumptions!$G$31-Assumptions!$F$31)*(Assumptions!$M$31-Assumptions!$L$31),Assumptions!$M$31))))))) -> 70 | T8: =IF(K8="","",IF(K8<=Assumptions!$B$32,Assumptions!$H$32,IF(K8<=Assumptions!$C$32,Assumptions!$H$32+(K8-Assumptions!$B$32)/(Assumptions!$C$32-Assumptions!$B$32)*(Assumptions!$I$32-Assumptions!$H$32),IF(K8<=Assumptions!$D$32,Assumptions!$I$32+(K8-Assumptions!$C$32)/(Assumptions!$D$32-Assumptions!$C$32)*(Assumptions!$J$32-Assumptions!$I$32),IF(K8<=Assumptions!$E$32,Assumptions!$J$32+(K8-Assumptions!$D$32)/(Assumptions!$E$32-Assumptions!$D$32)*(Assumptions!$K$32-Assumptions!$J$32),IF(K8<=Assumptions!$F$32,Assumptions!$K$32+(K8-Assumptions!$E$32)/(Assumptions!$F$32-Assumptions!$E$32)*(Assumptions!$L$32-Assumptions!$K$32),IF(K8<=Assumptions!$G$32,Assumptions!$L$32+(K8-Assumptions!$F$32)/(Assumptions!$G$32-Assumptions!$F$32)*(Assumptions!$M$32-Assumptions!$L$32),Assumptions!$M$32))))))) -> 4.8 | U8: =IF(M8<=Assumptions!$B$33,Assumptions!$H$33,IF(M8<=Assumptions!$C$33,Assumptions!$H$33+(M8-Assumptions!$B$33)/(Assumptions!$C$33-Assumptions!$B$33)*(Assumptions!$I$33-Assumptions!$H$33),IF(M8<=Assumptions!$D$33,Assumptions!$I$33+(M8-Assumptions!$C$33)/(Assumptions!$D$33-Assumptions!$C$33)*(Assumptions!$J$33-Assumptions!$I$33),IF(M8<=Assumptions!$E$33,Assumptions!$J$33+(M8-Assumptions!$D$33)/(Assumptions!$E$33-Assumptions!$D$33)*(Assumptions!$K$33-Assumptions!$J$33),IF(M8<=Assumptions!$F$33,Assumptions!$K$33+(M8-Assumptions!$E$33)/(Assumptions!$F$33-Assumptions!$E$33)*(Assumptions!$L$33-Assumptions!$K$33),IF(M8<=Assumptions!$G$33,Assumptions!$L$33+(M8-Assumptions!$F$33)/(Assumptions!$G$33-Assumptions!$F$33)*(Assumptions!$M$33-Assumptions!$L$33),Assumptions!$M$33)))))) -> 58.5 | V8: =IF(N8<=Assumptions!$B$34,Assumptions!$H$34,IF(N8<=Assumptions!$C$34,Assumptions!$H$34+(N8-Assumptions!$B$34)/(Assumptions!$C$34-Assumptions!$B$34)*(Assumptions!$I$34-Assumptions!$H$34),IF(N8<=Assumptions!$D$34,Assumptions!$I$34+(N8-Assumptions!$C$34)/(Assumptions!$D$34-Assumptions!$C$34)*(Assumptions!$J$34-Assumptions!$I$34),IF(N8<=Assumptions!$E$34,Assumptions!$J$34+(N8-Assumptions!$D$34)/(Assumptions!$E$34-Assumptions!$D$34)*(Assumptions!$K$34-Assumptions!$J$34),IF(N8<=Assumptions!$F$34,Assumptions!$K$34+(N8-Assumptions!$E$34)/(Assumptions!$F$34-Assumptions!$E$34)*(Assumptions!$L$34-Assumptions!$K$34),IF(N8<=Assumptions!$G$34,Assumptions!$L$34+(N8-Assumptions!$F$34)/(Assumptions!$G$34-Assumptions!$F$34)*(Assumptions!$M$34-Assumptions!$L$34),Assumptions!$M$34)))))) -> 37 | W8: =IF(S8="",PERCENTILE($S$6:$S$30,Assumptions!$B$36),S8) -> 70 | X8: =IF(T8="",PERCENTILE($T$6:$T$30,Assumptions!$B$36),T8) -> 4.8 | Y8: =IF(O8="",PERCENTILE($O$6:$O$30,Assumptions!$B$36),O8) -> 42 | Z8: =W8*Assumptions!$B$16+X8*Assumptions!$B$17 -> 37.4 | AA8: =U8*Assumptions!$B$18+V8*Assumptions!$B$19 -> 47.75 | AB8: =AVERAGE(P8:R8) -> 57.333333 | AC8: 0 | AD8: =MIN(100,Z8*Assumptions!$B$11+AA8*Assumptions!$B$12+Y8*Assumptions!$B$13+AB8*Assumptions!$B$14+AC8*Assumptions!$B$20) -> 46.178333 | AE8: =MIN(1,SUMIFS(Network!$V$5:$V$14,Network!$D$5:$D$14,$A8,Network!$U$5:$U$14,1)) -> 1 | AF8: =MIN(1,SUMIFS(Network!$W$5:$W$14,Network!$D$5:$D$14,$A8,Network!$U$5:$U$14,1)) -> 1 | AG8: =MIN(1,SUMIFS(Network!$X$5:$X$14,Network!$D$5:$D$14,$A8,Network!$U$5:$U$14,1)) -> 1 | AH8: =AE8*Assumptions!$B$5+AF8*Assumptions!$B$6+AG8*Assumptions!$B$7 -> 1560 | AI8: =AH8/Assumptions!$B$8 -> 1 | AJ8: =AH8/52 -> 30 | AK8: =AJ8*I8 -> 360 | AL8: =MIN(100,I8/Assumptions!$B$26*100) -> 33.333333 | AM8: =MIN(100,H8/Assumptions!$B$27*100) -> 33.333333 | AN8: =AI8*100*Assumptions!$B$23+AL8*Assumptions!$B$24+AM8*Assumptions!$B$25 -> 66.666667 | AO8: =AN8*AD8/100 -> 30.785556 | AP8: =RANK(AO8,$AO$6:$AO$30)+COUNTIF($AO$6:AO8,AO8)-1 -> 9 | AQ8: =IF(AO8>=Assumptions!$B$39,"Critical",IF(AO8>=Assumptions!$B$40,"High",IF(AO8>=Assumptions!$B$41,"Elevated","Watch"))) -> High | AR8: =IF(AND(AN8>=Assumptions!$B$42,AD8>=Assumptions!$B$43),"Act now",IF(AN8>=Assumptions!$B$42,"Protect (structural)",IF(AD8>=Assumptions!$B$43,"Remediate supplier","Routine"))) -> Act now | AS8: =_xlfn.MAXIFS(Network!$T$5:$T$36,Network!$D$5:$D$36,$A8) -> 3 | AT8: =COUNT(K8:R8) -> 8 | AU8: =IF(AT8>=8,2,IF(AT8>=6,1,0)) -> 2 | AV8: =IF(OR(C8=1,LEFT(G8,9)="Confirmed"),1,0) -> 1 | AW8: =AS8+AU8+AV8 -> 6 | AX8: =IF(AW8>=Assumptions!$B$44,"High",IF(AW8>=Assumptions!$B$45,"Medium","Low")) -> High | AY8: =IF(OR(AQ8="Critical",AQ8="High"),IF(AX8="Low","VERIFY first – urgent sub-tier fact-find",IF(OR(AQ8="Critical",AV8=1),"ACT – mitigate now","CONFIRM sole-source status, then qualify alternate")),IF(AQ8="Elevated",IF(AX8="Low","VERIFY – add to N-tier survey","PLAN – qualify alternate in 90 days"),"MONITOR – quarterly review")) -> ACT – mitigate now | AZ8: =IF(K8&L8&O8<>"",IF(OR(K8="",L8="",O8=""),TRIM(IF(K8="","Current ratio; ","")&IF(L8="","Net debt/EBITDA; ","")&IF(O8="","Assurance gap","")),"—"),"Current ratio; Net debt/EBITDA; Assurance gap") -> —
A9: ORG-922 | B9: =INDEX(Data!$B$5:$B$34,MATCH($A9,Data!$A$5:$A$34,0)) -> Delta Capacitor Works Ltd. | C9: 1 | D9: Tier-1: C20 DC-link capacitor (P1,P2) | E9: =INDEX(Data!$G$38:$G$67,MATCH($A9,Data!$A$38:$A$67,0)) -> SITE-039 | F9: =INDEX(Data!$I$38:$I$67,MATCH($A9,Data!$A$38:$A$67,0)) -> Z03 | G9: Confirmed sole (100% allocation) | H9: 1 | I9: 8 | J9: Case: C20 qualification 8 wks | K9: =IF(INDEX(Data!$C$5:$C$34,MATCH($A9,Data!$A$5:$A$34,0))="","",INDEX(Data!$C$5:$C$34,MATCH($A9,Data!$A$5:$A$34,0))) -> 1.82 | L9: =IF(INDEX(Data!$D$5:$D$34,MATCH($A9,Data!$A$5:$A$34,0))="","",INDEX(Data!$D$5:$D$34,MATCH($A9,Data!$A$5:$A$34,0))) -> 1.67 | M9: =IF(INDEX(Data!$E$5:$E$34,MATCH($A9,Data!$A$5:$A$34,0))="","",INDEX(Data!$E$5:$E$34,MATCH($A9,Data!$A$5:$A$34,0))) -> 86.9 | N9: =IF(INDEX(Data!$F$5:$F$34,MATCH($A9,Data!$A$5:$A$34,0))="","",INDEX(Data!$F$5:$F$34,MATCH($A9,Data!$A$5:$A$34,0))) -> 2.2 | O9: =IF(INDEX(Data!$G$5:$G$34,MATCH($A9,Data!$A$5:$A$34,0))="","",INDEX(Data!$G$5:$G$34,MATCH($A9,Data!$A$5:$A$34,0))) -> 51 | P9: =IF(INDEX(Data!$H$5:$H$34,MATCH($A9,Data!$A$5:$A$34,0))="","",INDEX(Data!$H$5:$H$34,MATCH($A9,Data!$A$5:$A$34,0))) -> 19 | Q9: =IF(INDEX(Data!$I$5:$I$34,MATCH($A9,Data!$A$5:$A$34,0))="","",INDEX(Data!$I$5:$I$34,MATCH($A9,Data!$A$5:$A$34,0))) -> 26 | R9: =IF(INDEX(Data!$J$5:$J$34,MATCH($A9,Data!$A$5:$A$34,0))="","",INDEX(Data!$J$5:$J$34,MATCH($A9,Data!$A$5:$A$34,0))) -> 25 | S9: =IF(L9="","",IF(L9<=Assumptions!$B$31,Assumptions!$H$31,IF(L9<=Assumptions!$C$31,Assumptions!$H$31+(L9-Assumptions!$B$31)/(Assumptions!$C$31-Assumptions!$B$31)*(Assumptions!$I$31-Assumptions!$H$31),IF(L9<=Assumptions!$D$31,Assumptions!$I$31+(L9-Assumptions!$C$31)/(Assumptions!$D$31-Assumptions!$C$31)*(Assumptions!$J$31-Assumptions!$I$31),IF(L9<=Assumptions!$E$31,Assumptions!$J$31+(L9-Assumptions!$D$31)/(Assumptions!$E$31-Assumptions!$D$31)*(Assumptions!$K$31-Assumptions!$J$31),IF(L9<=Assumptions!$F$31,Assumptions!$K$31+(L9-Assumptions!$E$31)/(Assumptions!$F$31-Assumptions!$E$31)*(Assumptions!$L$31-Assumptions!$K$31),IF(L9<=Assumptions!$G$31,Assumptions!$L$31+(L9-Assumptions!$F$31)/(Assumptions!$G$31-Assumptions!$F$31)*(Assumptions!$M$31-Assumptions!$L$31),Assumptions!$M$31))))))) -> 20.04 | T9: =IF(K9="","",IF(K9<=Assumptions!$B$32,Assumptions!$H$32,IF(K9<=Assumptions!$C$32,Assumptions!$H$32+(K9-Assumptions!$B$32)/(Assumptions!$C$32-Assumptions!$B$32)*(Assumptions!$I$32-Assumptions!$H$32),IF(K9<=Assumptions!$D$32,Assumptions!$I$32+(K9-Assumptions!$C$32)/(Assumptions!$D$32-Assumptions!$C$32)*(Assumptions!$J$32-Assumptions!$I$32),IF(K9<=Assumptions!$E$32,Assumptions!$J$32+(K9-Assumptions!$D$32)/(Assumptions!$E$32-Assumptions!$D$32)*(Assumptions!$K$32-Assumptions!$J$32),IF(K9<=Assumptions!$F$32,Assumptions!$K$32+(K9-Assumptions!$E$32)/(Assumptions!$F$32-Assumptions!$E$32)*(Assumptions!$L$32-Assumptions!$K$32),IF(K9<=Assumptions!$G$32,Assumptions!$L$32+(K9-Assumptions!$F$32)/(Assumptions!$G$32-Assumptions!$F$32)*(Assumptions!$M$32-Assumptions!$L$32),Assumptions!$M$32))))))) -> 20.4 | U9: =IF(M9<=Assumptions!$B$33,Assumptions!$H$33,IF(M9<=Assumptions!$C$33,Assumptions!$H$33+(M9-Assumptions!$B$33)/(Assumptions!$C$33-Assumptions!$B$33)*(Assumptions!$I$33-Assumptions!$H$33),IF(M9<=Assumptions!$D$33,Assumptions!$I$33+(M9-Assumptions!$C$33)/(Assumptions!$D$33-Assumptions!$C$33)*(Assumptions!$J$33-Assumptions!$I$33),IF(M9<=Assumptions!$E$33,Assumptions!$J$33+(M9-Assumptions!$D$33)/(Assumptions!$E$33-Assumptions!$D$33)*(Assumptions!$K$33-Assumptions!$J$33),IF(M9<=Assumptions!$F$33,Assumptions!$K$33+(M9-Assumptions!$E$33)/(Assumptions!$F$33-Assumptions!$E$33)*(Assumptions!$L$33-Assumptions!$K$33),IF(M9<=Assumptions!$G$33,Assumptions!$L$33+(M9-Assumptions!$F$33)/(Assumptions!$G$33-Assumptions!$F$33)*(Assumptions!$M$33-Assumptions!$L$33),Assumptions!$M$33)))))) -> 40.5 | V9: =IF(N9<=Assumptions!$B$34,Assumptions!$H$34,IF(N9<=Assumptions!$C$34,Assumptions!$H$34+(N9-Assumptions!$B$34)/(Assumptions!$C$34-Assumptions!$B$34)*(Assumptions!$I$34-Assumptions!$H$34),IF(N9<=Assumptions!$D$34,Assumptions!$I$34+(N9-Assumptions!$C$34)/(Assumptions!$D$34-Assumptions!$C$34)*(Assumptions!$J$34-Assumptions!$I$34),IF(N9<=Assumptions!$E$34,Assumptions!$J$34+(N9-Assumptions!$D$34)/(Assumptions!$E$34-Assumptions!$D$34)*(Assumptions!$K$34-Assumptions!$J$34),IF(N9<=Assumptions!$F$34,Assumptions!$K$34+(N9-Assumptions!$E$34)/(Assumptions!$F$34-Assumptions!$E$34)*(Assumptions!$L$34-Assumptions!$K$34),IF(N9<=Assumptions!$G$34,Assumptions!$L$34+(N9-Assumptions!$F$34)/(Assumptions!$G$34-Assumptions!$F$34)*(Assumptions!$M$34-Assumptions!$L$34),Assumptions!$M$34)))))) -> 0 | W9: =IF(S9="",PERCENTILE($S$6:$S$30,Assumptions!$B$36),S9) -> 20.04 | X9: =IF(T9="",PERCENTILE($T$6:$T$30,Assumptions!$B$36),T9) -> 20.4 | Y9: =IF(O9="",PERCENTILE($O$6:$O$30,Assumptions!$B$36),O9) -> 51 | Z9: =W9*Assumptions!$B$16+X9*Assumptions!$B$17 -> 20.22 | AA9: =U9*Assumptions!$B$18+V9*Assumptions!$B$19 -> 20.25 | AB9: =AVERAGE(P9:R9) -> 23.333333 | AC9: 0 | AD9: =MIN(100,Z9*Assumptions!$B$11+AA9*Assumptions!$B$12+Y9*Assumptions!$B$13+AB9*Assumptions!$B$14+AC9*Assumptions!$B$20) -> 25.624333 | AE9: =MIN(1,SUMIFS(Network!$V$5:$V$14,Network!$D$5:$D$14,$A9,Network!$U$5:$U$14,1)) -> 1 | AF9: =MIN(1,SUMIFS(Network!$W$5:$W$14,Network!$D$5:$D$14,$A9,Network!$U$5:$U$14,1)) -> 1 | AG9: =MIN(1,SUMIFS(Network!$X$5:$X$14,Network!$D$5:$D$14,$A9,Network!$U$5:$U$14,1)) -> 0 | AH9: =AE9*Assumptions!$B$5+AF9*Assumptions!$B$6+AG9*Assumptions!$B$7 -> 1144 | AI9: =AH9/Assumptions!$B$8 -> 0.73333333 | AJ9: =AH9/52 -> 22 | AK9: =AJ9*I9 -> 176 | AL9: =MIN(100,I9/Assumptions!$B$26*100) -> 22.222222 | AM9: =MIN(100,H9/Assumptions!$B$27*100) -> 33.333333 | AN9: =AI9*100*Assumptions!$B$23+AL9*Assumptions!$B$24+AM9*Assumptions!$B$25 -> 50 | AO9: =AN9*AD9/100 -> 12.812167 | AP9: =RANK(AO9,$AO$6:$AO$30)+COUNTIF($AO$6:AO9,AO9)-1 -> 20 | AQ9: =IF(AO9>=Assumptions!$B$39,"Critical",IF(AO9>=Assumptions!$B$40,"High",IF(AO9>=Assumptions!$B$41,"Elevated","Watch"))) -> Watch | AR9: =IF(AND(AN9>=Assumptions!$B$42,AD9>=Assumptions!$B$43),"Act now",IF(AN9>=Assumptions!$B$42,"Protect (structural)",IF(AD9>=Assumptions!$B$43,"Remediate supplier","Routine"))) -> Routine | AS9: =_xlfn.MAXIFS(Network!$T$5:$T$36,Network!$D$5:$D$36,$A9) -> 3 | AT9: =COUNT(K9:R9) -> 8 | AU9: =IF(AT9>=8,2,IF(AT9>=6,1,0)) -> 2 | AV9: =IF(OR(C9=1,LEFT(G9,9)="Confirmed"),1,0) -> 1 | AW9: =AS9+AU9+AV9 -> 6 | AX9: =IF(AW9>=Assumptions!$B$44,"High",IF(AW9>=Assumptions!$B$45,"Medium","Low")) -> High | AY9: =IF(OR(AQ9="Critical",AQ9="High"),IF(AX9="Low","VERIFY first – urgent sub-tier fact-find",IF(OR(AQ9="Critical",AV9=1),"ACT – mitigate now","CONFIRM sole-source status, then qualify alternate")),IF(AQ9="Elevated",IF(AX9="Low","VERIFY – add to N-tier survey","PLAN – qualify alternate in 90 days"),"MONITOR – quarterly review")) -> MONITOR – quarterly review | AZ9: =IF(K9&L9&O9<>"",IF(OR(K9="",L9="",O9=""),TRIM(IF(K9="","Current ratio; ","")&IF(L9="","Net debt/EBITDA; ","")&IF(O9="","Assurance gap","")),"—"),"Current ratio; Net debt/EBITDA; Assurance gap") -> —
A10: ORG-786 | B10: =INDEX(Data!$B$5:$B$34,MATCH($A10,Data!$A$5:$A$34,0)) -> Estuary Thermal Systems Ltd. | C10: 1 | D10: Tier-1: H20 cooling (P2,P3) | E10: =INDEX(Data!$G$38:$G$67,MATCH($A10,Data!$A$38:$A$67,0)) -> SITE-046 | F10: =INDEX(Data!$I$38:$I$67,MATCH($A10,Data!$A$38:$A$67,0)) -> Z06 | G10: Confirmed sole (100% allocation) | H10: 1 | I10: 6 | J10: Case: H20 qualification 6 wks | K10: =IF(INDEX(Data!$C$5:$C$34,MATCH($A10,Data!$A$5:$A$34,0))="","",INDEX(Data!$C$5:$C$34,MATCH($A10,Data!$A$5:$A$34,0))) -> 2.53 | L10: =IF(INDEX(Data!$D$5:$D$34,MATCH($A10,Data!$A$5:$A$34,0))="","",INDEX(Data!$D$5:$D$34,MATCH($A10,Data!$A$5:$A$34,0))) -> 2.67 | M10: =IF(INDEX(Data!$E$5:$E$34,MATCH($A10,Data!$A$5:$A$34,0))="","",INDEX(Data!$E$5:$E$34,MATCH($A10,Data!$A$5:$A$34,0))) -> 89.7 | N10: =IF(INDEX(Data!$F$5:$F$34,MATCH($A10,Data!$A$5:$A$34,0))="","",INDEX(Data!$F$5:$F$34,MATCH($A10,Data!$A$5:$A$34,0))) -> 1.8 | O10: =IF(INDEX(Data!$G$5:$G$34,MATCH($A10,Data!$A$5:$A$34,0))="","",INDEX(Data!$G$5:$G$34,MATCH($A10,Data!$A$5:$A$34,0))) -> 60 | P10: =IF(INDEX(Data!$H$5:$H$34,MATCH($A10,Data!$A$5:$A$34,0))="","",INDEX(Data!$H$5:$H$34,MATCH($A10,Data!$A$5:$A$34,0))) -> 67 | Q10: =IF(INDEX(Data!$I$5:$I$34,MATCH($A10,Data!$A$5:$A$34,0))="","",INDEX(Data!$I$5:$I$34,MATCH($A10,Data!$A$5:$A$34,0))) -> 59 | R10: =IF(INDEX(Data!$J$5:$J$34,MATCH($A10,Data!$A$5:$A$34,0))="","",INDEX(Data!$J$5:$J$34,MATCH($A10,Data!$A$5:$A$34,0))) -> 54 | S10: =IF(L10="","",IF(L10<=Assumptions!$B$31,Assumptions!$H$31,IF(L10<=Assumptions!$C$31,Assumptions!$H$31+(L10-Assumptions!$B$31)/(Assumptions!$C$31-Assumptions!$B$31)*(Assumptions!$I$31-Assumptions!$H$31),IF(L10<=Assumptions!$D$31,Assumptions!$I$31+(L10-Assumptions!$C$31)/(Assumptions!$D$31-Assumptions!$C$31)*(Assumptions!$J$31-Assumptions!$I$31),IF(L10<=Assumptions!$E$31,Assumptions!$J$31+(L10-Assumptions!$D$31)/(Assumptions!$E$31-Assumptions!$D$31)*(Assumptions!$K$31-Assumptions!$J$31),IF(L10<=Assumptions!$F$31,Assumptions!$K$31+(L10-Assumptions!$E$31)/(Assumptions!$F$31-Assumptions!$E$31)*(Assumptions!$L$31-Assumptions!$K$31),IF(L10<=Assumptions!$G$31,Assumptions!$L$31+(L10-Assumptions!$F$31)/(Assumptions!$G$31-Assumptions!$F$31)*(Assumptions!$M$31-Assumptions!$L$31),Assumptions!$M$31))))))) -> 34.533333 | T10: =IF(K10="","",IF(K10<=Assumptions!$B$32,Assumptions!$H$32,IF(K10<=Assumptions!$C$32,Assumptions!$H$32+(K10-Assumptions!$B$32)/(Assumptions!$C$32-Assumptions!$B$32)*(Assumptions!$I$32-Assumptions!$H$32),IF(K10<=Assumptions!$D$32,Assumptions!$I$32+(K10-Assumptions!$C$32)/(Assumptions!$D$32-Assumptions!$C$32)*(Assumptions!$J$32-Assumptions!$I$32),IF(K10<=Assumptions!$E$32,Assumptions!$J$32+(K10-Assumptions!$D$32)/(Assumptions!$E$32-Assumptions!$D$32)*(Assumptions!$K$32-Assumptions!$J$32),IF(K10<=Assumptions!$F$32,Assumptions!$K$32+(K10-Assumptions!$E$32)/(Assumptions!$F$32-Assumptions!$E$32)*(Assumptions!$L$32-Assumptions!$K$32),IF(K10<=Assumptions!$G$32,Assumptions!$L$32+(K10-Assumptions!$F$32)/(Assumptions!$G$32-Assumptions!$F$32)*(Assumptions!$M$32-Assumptions!$L$32),Assumptions!$M$32))))))) -> 0 | U10: =IF(M10<=Assumptions!$B$33,Assumptions!$H$33,IF(M10<=Assumptions!$C$33,Assumptions!$H$33+(M10-Assumptions!$B$33)/(Assumptions!$C$33-Assumptions!$B$33)*(Assumptions!$I$33-Assumptions!$H$33),IF(M10<=Assumptions!$D$33,Assumptions!$I$33+(M10-Assumptions!$C$33)/(Assumptions!$D$33-Assumptions!$C$33)*(Assumptions!$J$33-Assumptions!$I$33),IF(M10<=Assumptions!$E$33,Assumptions!$J$33+(M10-Assumptions!$D$33)/(Assumptions!$E$33-Assumptions!$D$33)*(Assumptions!$K$33-Assumptions!$J$33),IF(M10<=Assumptions!$F$33,Assumptions!$K$33+(M10-Assumptions!$E$33)/(Assumptions!$F$33-Assumptions!$E$33)*(Assumptions!$L$33-Assumptions!$K$33),IF(M10<=Assumptions!$G$33,Assumptions!$L$33+(M10-Assumptions!$F$33)/(Assumptions!$G$33-Assumptions!$F$33)*(Assumptions!$M$33-Assumptions!$L$33),Assumptions!$M$33)))))) -> 26.5 | V10: =IF(N10<=Assumptions!$B$34,Assumptions!$H$34,IF(N10<=Assumptions!$C$34,Assumptions!$H$34+(N10-Assumptions!$B$34)/(Assumptions!$C$34-Assumptions!$B$34)*(Assumptions!$I$34-Assumptions!$H$34),IF(N10<=Assumptions!$D$34,Assumptions!$I$34+(N10-Assumptions!$C$34)/(Assumptions!$D$34-Assumptions!$C$34)*(Assumptions!$J$34-Assumptions!$I$34),IF(N10<=Assumptions!$E$34,Assumptions!$J$34+(N10-Assumptions!$D$34)/(Assumptions!$E$34-Assumptions!$D$34)*(Assumptions!$K$34-Assumptions!$J$34),IF(N10<=Assumptions!$F$34,Assumptions!$K$34+(N10-Assumptions!$E$34)/(Assumptions!$F$34-Assumptions!$E$34)*(Assumptions!$L$34-Assumptions!$K$34),IF(N10<=Assumptions!$G$34,Assumptions!$L$34+(N10-Assumptions!$F$34)/(Assumptions!$G$34-Assumptions!$F$34)*(Assumptions!$M$34-Assumptions!$L$34),Assumptions!$M$34)))))) -> 2 | W10: =IF(S10="",PERCENTILE($S$6:$S$30,Assumptions!$B$36),S10) -> 34.533333 | X10: =IF(T10="",PERCENTILE($T$6:$T$30,Assumptions!$B$36),T10) -> 0 | Y10: =IF(O10="",PERCENTILE($O$6:$O$30,Assumptions!$B$36),O10) -> 60 | Z10: =W10*Assumptions!$B$16+X10*Assumptions!$B$17 -> 17.266667 | AA10: =U10*Assumptions!$B$18+V10*Assumptions!$B$19 -> 14.25 | AB10: =AVERAGE(P10:R10) -> 60 | AC10: 0 | AD10: =MIN(100,Z10*Assumptions!$B$11+AA10*Assumptions!$B$12+Y10*Assumptions!$B$13+AB10*Assumptions!$B$14+AC10*Assumptions!$B$20) -> 33.455 | AE10: =MIN(1,SUMIFS(Network!$V$5:$V$14,Network!$D$5:$D$14,$A10,Network!$U$5:$U$14,1)) -> 0 | AF10: =MIN(1,SUMIFS(Network!$W$5:$W$14,Network!$D$5:$D$14,$A10,Network!$U$5:$U$14,1)) -> 1 | AG10: =MIN(1,SUMIFS(Network!$X$5:$X$14,Network!$D$5:$D$14,$A10,Network!$U$5:$U$14,1)) -> 1 | AH10: =AE10*Assumptions!$B$5+AF10*Assumptions!$B$6+AG10*Assumptions!$B$7 -> 936 | AI10: =AH10/Assumptions!$B$8 -> 0.6 | AJ10: =AH10/52 -> 18 | AK10: =AJ10*I10 -> 108 | AL10: =MIN(100,I10/Assumptions!$B$26*100) -> 16.666667 | AM10: =MIN(100,H10/Assumptions!$B$27*100) -> 33.333333 | AN10: =AI10*100*Assumptions!$B$23+AL10*Assumptions!$B$24+AM10*Assumptions!$B$25 -> 41.666667 | AO10: =AN10*AD10/100 -> 13.939583 | AP10: =RANK(AO10,$AO$6:$AO$30)+COUNTIF($AO$6:AO10,AO10)-1 -> 18 | AQ10: =IF(AO10>=Assumptions!$B$39,"Critical",IF(AO10>=Assumptions!$B$40,"High",IF(AO10>=Assumptions!$B$41,"Elevated","Watch"))) -> Watch | AR10: =IF(AND(AN10>=Assumptions!$B$42,AD10>=Assumptions!$B$43),"Act now",IF(AN10>=Assumptions!$B$42,"Protect (structural)",IF(AD10>=Assumptions!$B$43,"Remediate supplier","Routine"))) -> Routine | AS10: =_xlfn.MAXIFS(Network!$T$5:$T$36,Network!$D$5:$D$36,$A10) -> 3 | AT10: =COUNT(K10:R10) -> 8 | AU10: =IF(AT10>=8,2,IF(AT10>=6,1,0)) -> 2 | AV10: =IF(OR(C10=1,LEFT(G10,9)="Confirmed"),1,0) -> 1 | AW10: =AS10+AU10+AV10 -> 6 | AX10: =IF(AW10>=Assumptions!$B$44,"High",IF(AW10>=Assumptions!$B$45,"Medium","Low")) -> High | AY10: =IF(OR(AQ10="Critical",AQ10="High"),IF(AX10="Low","VERIFY first – urgent sub-tier fact-find",IF(OR(AQ10="Critical",AV10=1),"ACT – mitigate now","CONFIRM sole-source status, then qualify alternate")),IF(AQ10="Elevated",IF(AX10="Low","VERIFY – add to N-tier survey","PLAN – qualify alternate in 90 days"),"MONITOR – quarterly review")) -> MONITOR – quarterly review | AZ10: =IF(K10&L10&O10<>"",IF(OR(K10="",L10="",O10=""),TRIM(IF(K10="","Current ratio; ","")&IF(L10="","Net debt/EBITDA; ","")&IF(O10="","Assurance gap","")),"—"),"Current ratio; Net debt/EBITDA; Assurance gap") -> —
A11: ORG-287 | B11: =INDEX(Data!$B$5:$B$34,MATCH($A11,Data!$A$5:$A$34,0)) -> ForgeLine Enclosures Ltd. | C11: 1 | D11: Tier-1: H10 housing (P1) | E11: =INDEX(Data!$G$38:$G$67,MATCH($A11,Data!$A$38:$A$67,0)) -> SITE-053 | F11: =INDEX(Data!$I$38:$I$67,MATCH($A11,Data!$A$38:$A$67,0)) -> Z02 | G11: Confirmed sole (100% allocation) | H11: 1 | I11: 4 | J11: Case: H10 qualification 4 wks | K11: =IF(INDEX(Data!$C$5:$C$34,MATCH($A11,Data!$A$5:$A$34,0))="","",INDEX(Data!$C$5:$C$34,MATCH($A11,Data!$A$5:$A$34,0))) -> 1.94 | L11: =IF(INDEX(Data!$D$5:$D$34,MATCH($A11,Data!$A$5:$A$34,0))="","",INDEX(Data!$D$5:$D$34,MATCH($A11,Data!$A$5:$A$34,0))) -> 3.67 | M11: =IF(INDEX(Data!$E$5:$E$34,MATCH($A11,Data!$A$5:$A$34,0))="","",INDEX(Data!$E$5:$E$34,MATCH($A11,Data!$A$5:$A$34,0))) -> 89.8 | N11: =IF(INDEX(Data!$F$5:$F$34,MATCH($A11,Data!$A$5:$A$34,0))="","",INDEX(Data!$F$5:$F$34,MATCH($A11,Data!$A$5:$A$34,0))) -> -0.3 | O11: =IF(INDEX(Data!$G$5:$G$34,MATCH($A11,Data!$A$5:$A$34,0))="","",INDEX(Data!$G$5:$G$34,MATCH($A11,Data!$A$5:$A$34,0))) -> 69 | P11: =IF(INDEX(Data!$H$5:$H$34,MATCH($A11,Data!$A$5:$A$34,0))="","",INDEX(Data!$H$5:$H$34,MATCH($A11,Data!$A$5:$A$34,0))) -> 27 | Q11: =IF(INDEX(Data!$I$5:$I$34,MATCH($A11,Data!$A$5:$A$34,0))="","",INDEX(Data!$I$5:$I$34,MATCH($A11,Data!$A$5:$A$34,0))) -> 30 | R11: =IF(INDEX(Data!$J$5:$J$34,MATCH($A11,Data!$A$5:$A$34,0))="","",INDEX(Data!$J$5:$J$34,MATCH($A11,Data!$A$5:$A$34,0))) -> 24 | S11: =IF(L11="","",IF(L11<=Assumptions!$B$31,Assumptions!$H$31,IF(L11<=Assumptions!$C$31,Assumptions!$H$31+(L11-Assumptions!$B$31)/(Assumptions!$C$31-Assumptions!$B$31)*(Assumptions!$I$31-Assumptions!$H$31),IF(L11<=Assumptions!$D$31,Assumptions!$I$31+(L11-Assumptions!$C$31)/(Assumptions!$D$31-Assumptions!$C$31)*(Assumptions!$J$31-Assumptions!$I$31),IF(L11<=Assumptions!$E$31,Assumptions!$J$31+(L11-Assumptions!$D$31)/(Assumptions!$E$31-Assumptions!$D$31)*(Assumptions!$K$31-Assumptions!$J$31),IF(L11<=Assumptions!$F$31,Assumptions!$K$31+(L11-Assumptions!$E$31)/(Assumptions!$F$31-Assumptions!$E$31)*(Assumptions!$L$31-Assumptions!$K$31),IF(L11<=Assumptions!$G$31,Assumptions!$L$31+(L11-Assumptions!$F$31)/(Assumptions!$G$31-Assumptions!$F$31)*(Assumptions!$M$31-Assumptions!$L$31),Assumptions!$M$31))))))) -> 61.2 | T11: =IF(K11="","",IF(K11<=Assumptions!$B$32,Assumptions!$H$32,IF(K11<=Assumptions!$C$32,Assumptions!$H$32+(K11-Assumptions!$B$32)/(Assumptions!$C$32-Assumptions!$B$32)*(Assumptions!$I$32-Assumptions!$H$32),IF(K11<=Assumptions!$D$32,Assumptions!$I$32+(K11-Assumptions!$C$32)/(Assumptions!$D$32-Assumptions!$C$32)*(Assumptions!$J$32-Assumptions!$I$32),IF(K11<=Assumptions!$E$32,Assumptions!$J$32+(K11-Assumptions!$D$32)/(Assumptions!$E$32-Assumptions!$D$32)*(Assumptions!$K$32-Assumptions!$J$32),IF(K11<=Assumptions!$F$32,Assumptions!$K$32+(K11-Assumptions!$E$32)/(Assumptions!$F$32-Assumptions!$E$32)*(Assumptions!$L$32-Assumptions!$K$32),IF(K11<=Assumptions!$G$32,Assumptions!$L$32+(K11-Assumptions!$F$32)/(Assumptions!$G$32-Assumptions!$F$32)*(Assumptions!$M$32-Assumptions!$L$32),Assumptions!$M$32))))))) -> 16.8 | U11: =IF(M11<=Assumptions!$B$33,Assumptions!$H$33,IF(M11<=Assumptions!$C$33,Assumptions!$H$33+(M11-Assumptions!$B$33)/(Assumptions!$C$33-Assumptions!$B$33)*(Assumptions!$I$33-Assumptions!$H$33),IF(M11<=Assumptions!$D$33,Assumptions!$I$33+(M11-Assumptions!$C$33)/(Assumptions!$D$33-Assumptions!$C$33)*(Assumptions!$J$33-Assumptions!$I$33),IF(M11<=Assumptions!$E$33,Assumptions!$J$33+(M11-Assumptions!$D$33)/(Assumptions!$E$33-Assumptions!$D$33)*(Assumptions!$K$33-Assumptions!$J$33),IF(M11<=Assumptions!$F$33,Assumptions!$K$33+(M11-Assumptions!$E$33)/(Assumptions!$F$33-Assumptions!$E$33)*(Assumptions!$L$33-Assumptions!$K$33),IF(M11<=Assumptions!$G$33,Assumptions!$L$33+(M11-Assumptions!$F$33)/(Assumptions!$G$33-Assumptions!$F$33)*(Assumptions!$M$33-Assumptions!$L$33),Assumptions!$M$33)))))) -> 26 | V11: =IF(N11<=Assumptions!$B$34,Assumptions!$H$34,IF(N11<=Assumptions!$C$34,Assumptions!$H$34+(N11-Assumptions!$B$34)/(Assumptions!$C$34-Assumptions!$B$34)*(Assumptions!$I$34-Assumptions!$H$34),IF(N11<=Assumptions!$D$34,Assumptions!$I$34+(N11-Assumptions!$C$34)/(Assumptions!$D$34-Assumptions!$C$34)*(Assumptions!$J$34-Assumptions!$I$34),IF(N11<=Assumptions!$E$34,Assumptions!$J$34+(N11-Assumptions!$D$34)/(Assumptions!$E$34-Assumptions!$D$34)*(Assumptions!$K$34-Assumptions!$J$34),IF(N11<=Assumptions!$F$34,Assumptions!$K$34+(N11-Assumptions!$E$34)/(Assumptions!$F$34-Assumptions!$E$34)*(Assumptions!$L$34-Assumptions!$K$34),IF(N11<=Assumptions!$G$34,Assumptions!$L$34+(N11-Assumptions!$F$34)/(Assumptions!$G$34-Assumptions!$F$34)*(Assumptions!$M$34-Assumptions!$L$34),Assumptions!$M$34)))))) -> 22.25 | W11: =IF(S11="",PERCENTILE($S$6:$S$30,Assumptions!$B$36),S11) -> 61.2 | X11: =IF(T11="",PERCENTILE($T$6:$T$30,Assumptions!$B$36),T11) -> 16.8 | Y11: =IF(O11="",PERCENTILE($O$6:$O$30,Assumptions!$B$36),O11) -> 69 | Z11: =W11*Assumptions!$B$16+X11*Assumptions!$B$17 -> 39 | AA11: =U11*Assumptions!$B$18+V11*Assumptions!$B$19 -> 24.125 | AB11: =AVERAGE(P11:R11) -> 27 | AC11: 0 | AD11: =MIN(100,Z11*Assumptions!$B$11+AA11*Assumptions!$B$12+Y11*Assumptions!$B$13+AB11*Assumptions!$B$14+AC11*Assumptions!$B$20) -> 36.0375 | AE11: =MIN(1,SUMIFS(Network!$V$5:$V$14,Network!$D$5:$D$14,$A11,Network!$U$5:$U$14,1)) -> 1 | AF11: =MIN(1,SUMIFS(Network!$W$5:$W$14,Network!$D$5:$D$14,$A11,Network!$U$5:$U$14,1)) -> 0 | AG11: =MIN(1,SUMIFS(Network!$X$5:$X$14,Network!$D$5:$D$14,$A11,Network!$U$5:$U$14,1)) -> 0 | AH11: =AE11*Assumptions!$B$5+AF11*Assumptions!$B$6+AG11*Assumptions!$B$7 -> 624 | AI11: =AH11/Assumptions!$B$8 -> 0.4 | AJ11: =AH11/52 -> 12 | AK11: =AJ11*I11 -> 48 | AL11: =MIN(100,I11/Assumptions!$B$26*100) -> 11.111111 | AM11: =MIN(100,H11/Assumptions!$B$27*100) -> 33.333333 | AN11: =AI11*100*Assumptions!$B$23+AL11*Assumptions!$B$24+AM11*Assumptions!$B$25 -> 30 | AO11: =AN11*AD11/100 -> 10.81125 | AP11: =RANK(AO11,$AO$6:$AO$30)+COUNTIF($AO$6:AO11,AO11)-1 -> 23 | AQ11: =IF(AO11>=Assumptions!$B$39,"Critical",IF(AO11>=Assumptions!$B$40,"High",IF(AO11>=Assumptions!$B$41,"Elevated","Watch"))) -> Watch | AR11: =IF(AND(AN11>=Assumptions!$B$42,AD11>=Assumptions!$B$43),"Act now",IF(AN11>=Assumptions!$B$42,"Protect (structural)",IF(AD11>=Assumptions!$B$43,"Remediate supplier","Routine"))) -> Routine | AS11: =_xlfn.MAXIFS(Network!$T$5:$T$36,Network!$D$5:$D$36,$A11) -> 3 | AT11: =COUNT(K11:R11) -> 8 | AU11: =IF(AT11>=8,2,IF(AT11>=6,1,0)) -> 2 | AV11: =IF(OR(C11=1,LEFT(G11,9)="Confirmed"),1,0) -> 1 | AW11: =AS11+AU11+AV11 -> 6 | AX11: =IF(AW11>=Assumptions!$B$44,"High",IF(AW11>=Assumptions!$B$45,"Medium","Low")) -> High | AY11: =IF(OR(AQ11="Critical",AQ11="High"),IF(AX11="Low","VERIFY first – urgent sub-tier fact-find",IF(OR(AQ11="Critical",AV11=1),"ACT – mitigate now","CONFIRM sole-source status, then qualify alternate")),IF(AQ11="Elevated",IF(AX11="Low","VERIFY – add to N-tier survey","PLAN – qualify alternate in 90 days"),"MONITOR – quarterly review")) -> MONITOR – quarterly review | AZ11: =IF(K11&L11&O11<>"",IF(OR(K11="",L11="",O11=""),TRIM(IF(K11="","Current ratio; ","")&IF(L11="","Net debt/EBITDA; ","")&IF(O11="","Assurance gap","")),"—"),"Current ratio; Net debt/EBITDA; Assurance gap") -> —
